Workbook

Sheet Executive Summary
B2: BUDGET EXECUTIVE SUMMARY
B3: FY2026 budget performance | Joy Deep Mukherjee
B5: Revenue vs Flexible Budget | C5: Revenue vs Static Budget | D5: DM Variance vs Flexible | E5: DL Variance vs Flexible | F5: Variable OH vs Flexible | G5: Fixed Costs vs Flexible
B6: +6.7% | C6: -4.8% | D6: +24.7% | E6: +26.6% | F6: -40.0% | G6: -40.5%
B7: Favourable | C7: Unfavourable | D7: Unfavourable | E7: Unfavourable | F7: Favourable | G7: Favourable
B9: Executive narrative
B10: 1. Volume is below the static plan but above the flexible benchmark: actual units sold are 4,500 versus 4,725 static budget, while the flexible budget resets to 4,500 units. This indicates the principal top-line gap to static budget is volume, not price.
B11: 2. Revenue quality is mixed: actual revenue of $925,000 is 6.7% above the flexible budget of $867,188, but 4.8% below the static budget of $971,250. The implied average selling price is $205.56 per unit versus $205.56 in the static plan, so the static shortfall is primarily the 225-unit volume gap.
B12: 3. Cost absorption is the main budget pressure. Direct materials are $99,203 versus $79,549 flexible budget (+24.7%) and direct labour is $157,500 versus $124,422 (+26.6%). These two items more than offset the 40.0% favourable variable-overhead variance.
B13: 4. Fixed manufacturing costs are $40,000 versus $67,250 flexible budget (-40.5%), providing substantial protection to operating profit. As a result, operating income is $604,297, 8.7% above the flexible budget, despite the adverse material and labour variances.
B14: 5. Against the static budget, operating income is 7.5% below plan. The budget story therefore depends heavily on flexible-budget interpretation: operational profitability is above the activity-adjusted benchmark, but the original plan was not fully achieved.
B15: 6. Forward budget: production grows from 4,725 units in FY26 to 6,044 in FY29 (~8.5% CAGR). The budget assumes continued growth in revenue and costs, while cash remains positive throughout the forecast horizon.
B17: Core budget variance bridge
B18: Metric | C18: Actual | D18: Flexible Budget | E18: Variance | F18: Var % | G18: Static Budget | H18: Vs Static | I18: Comment
B19: Units sold | C19: 4500 | D19: 4500 | E19: 0 | F19: 0 | G19: 4725 | H19: -225 | I19: Volume 4.8% below static plan
B20: Revenue | C20: 925000 | D20: 867187.5 | E20: 57812.5 | F20: 0.066667 | G20: 971250 | H20: -46250 | I20: Above activity-adjusted budget; below original plan
B21: Direct materials | C21: 99202.812 | D21: 79549 | E21: 19653.812 | F21: 0.247065 | G21: 79202.812 | H21: 20000 | I21: Major adverse cost variance; reconcile to master budget
B22: Direct labour | C22: 157500 | D22: 124422 | E22: 33078 | F22: 0.265853 | G22: 137500 | H22: 20000 | I22: Hours/rates materially above flexible plan
B23: Variable manufacturing OH | C23: 24000 | D23: 40000 | E23: -16000 | F23: -0.4 | G23: 36000 | H23: -12000 | I23: Favourable, but investigate whether budget basis is consistent
B24: Fixed costs | C24: 40000 | D24: 67250 | E24: -27250 | F24: -0.405204 | G24: 65000 | H24: -25000 | I24: Favourable; validate whether planned spend is committed/deferred
B25: Contribution margin | C25: 644297.19 | D25: 623216.5 | E25: 21080.688 | F25: 0.033826 | G25: 718547.19 | H25: -74250 | I25: Higher than flexible budget, below static plan
B26: Operating income | C26: 604297.19 | D26: 555966.5 | E26: 48330.688 | F26: 0.086931 | G26: 653547.19 | H26: -49250 | I26: Favourable vs flex; below static budget
B27: Product-level standard budget economics
B28: Product | C28: Units produced | D28: Revenue / unit | E28: DM / unit | F28: DL / unit | G28: OH / unit | H28: Standard cost / unit | I28: Budget margin / unit
B29: Nameplates | C29: 2100 | D29: 200 | E29: 10 | F29: 30 | G29: 7.6190476 | H29: 47.619048 | I29: 152.38095
B30: Frames | C30: 1575 | D30: 150 | E30: 10.5 | F30: 40 | G30: 20.238095 | H30: 65.738095 | I30: 84.261905
B31: Engraved Items | C31: 1050 | D31: 300 | E31: 10 | F31: 30 | G31: 22.857143 | H31: 62.857143 | I31: 237.14286
B34: Forward budget outlook
B35: Metric | C35: FY26 | D35: FY27 | E35: FY28 | F35: FY29 | G35: FY30 | H35: Trend / implication
B36: Units produced | C36: 4725 | D36: 4995 | E36: 5494.5 | F36: 6043.95 | H36: ~8.5% CAGR through FY29
B37: COGS | C37: 256702.38 | D37: 309487.62 | E37: 380359.47 | F37: 477440.7 | H37: Budgeted cost grows faster than units; monitor margin
B38: Ending cash after finance cost | C38: 1200187.7 | D38: 1888787.8 | E38: 2744437 | F38: 4028365.4 | G38: 5813550.5 | H38: Positive throughout; liquidity buffer builds
B40: Scope: budget-related analysis only, using the Sales Budget, Production Budget, Direct Materials Usage/Purchases, Direct Labour, Manufacturing Overhead, Standard Costs, Inventory, COGS, Cash Budget and Variance Analysis schedules.

Sheet Variance Analysis
A1: Category | B1: Actual Results | C1: Actual vs Flexible Variance | D1: Favourable/ Unfavourable | E1: Flexible Budget | F1: Flexible vs Static Variance | G1: Favourable/ Unfavourable | H1: Static Budget | I1: Static vs Actual Variance | J1: Favourable/ Unfavourable
A2: Units sold | B2: =SUM('Master Budget'!B4:B6) -> 4500 | C2: =(B2-E2)/E2 -> 0 | D2: =IF(B2>=E2,"F","U") -> F | E2: =SUM('Master Budget'!B4:B6) -> 4500 | F2: =(E2-H2)/H2 -> -0.047619048 | G2: =IF(E2>=H2,"F","U") -> U | H2: =SUM('Master Budget'!B77:D77) -> 4725 | I2: =(H2-B2)/B2 -> 0.05 | J2: =IF(B2>=H2,"F","U") -> U
A3: Revenues | B3: ='Income Statement'!F8 -> 925000 | C3: =(B3-E3)/E3 -> 0.066666667 | D3: =IF(B3>=E3,"F","U") -> F | E3: ='Forecasted Budget'!G4 -> 867187.5 | F3: =(E3-H3)/H3 -> -0.10714286 | G3: =IF(E3>=H3,"F","U") -> U | H3: =(B3/B2)*H2 -> 971250 | I3: =(H3-B3)/B3 -> 0.05 | J3: =IF(B3>=H3,"F","U") -> U
A4: Variable costs
A5: Direct materials | B5: ='Master Budget'!D30+'Master Budget'!D45-475 -> 99202.812 | C5: =(B5-E5)/E5 -> 0.24706549 | D5: =IF(B5<=E5,"F","U") -> U | E5: 79549 | F5: =(E5-H5)/H5 -> 0.0043708991 | G5: =IF(E5<=H5,"F","U") -> U | H5: 79202.812 | I5: =(H5-B5)/B5 -> -0.20160719 | J5: =IF(B5<=H5,"F","U") -> U
A6: Direct manufacturing labor | B6: ='Master Budget'!D56 -> 157500 | C6: =(B6-E6)/E6 -> 0.26585331 | D6: =IF(B6<=E6,"F","U") -> U | E6: 124422 | F6: =(E6-H6)/H6 -> -0.095112727 | G6: =IF(E6<=H6,"F","U") -> F | H6: 137500 | I6: =(H6-B6)/B6 -> -0.12698413 | J6: =IF(B6<=H6,"F","U") -> U
A7: Variable manufacturing overhead | B7: ='Master Budget'!D65 -> 24000 | C7: =(B7-E7)/E7 -> -0.4 | D7: =IF(B7<=E7,"F","U") -> F | E7: 40000 | F7: =(E7-H7)/H7 -> 0.11111111 | G7: =IF(E7<=H7,"F","U") -> U | H7: 36000 | I7: =(H7-B7)/B7 -> 0.5 | J7: =IF(B7<=H7,"F","U") -> F
A8: Total variable costs | B8: =SUM(B5:B7) -> 280702.81 | C8: =(B8-E8)/E8 -> 0.15055811 | D8: =IF(B8<=E8,"F","U") -> U | E8: =SUM(E5:E7) -> 243971 | F8: =(E8-H8)/H8 -> -0.034553682 | G8: =IF(E8<=H8,"F","U") -> F | H8: =SUM(H5:H7) -> 252702.81 | I8: =(H8-B8)/B8 -> -0.099749624 | J8: =IF(B8<=H8,"F","U") -> U
A9: Contribution margin | B9: =B3-B8 -> 644297.19 | C9: =(B9-E9)/E9 -> 0.033825625 | D9: =IF(B9>=E9,"F","U") -> F | E9: =E3-E8 -> 623216.5 | F9: =(E9-H9)/H9 -> -0.13267144 | G9: =IF(E9>=H9,"F","U") -> U | H9: =H3-H8 -> 718547.19 | I9: =(H9-B9)/B9 -> 0.11524185 | J9: =IF(B9>=H9,"F","U") -> U
A10: Fixed costs | B10: ='Master Budget'!B65 -> 40000 | C10: =(B10-E10)/E10 -> -0.40520446 | D10: =IF(B10<=E10,"F","U") -> F | E10: 67250 | F10: =(E10-H10)/H10 -> 0.034615385 | G10: =IF(E10<=H10,"F","U") -> U | H10: 65000 | I10: =(H10-B10)/B10 -> 0.625 | J10: =IF(B10<=H10,"F","U") -> F
A11: Operating income | B11: =B9-B10 -> 604297.19 | C11: =(B11-E11)/E11 -> 0.086930935 | D11: =IF(B11>=E11,"F","U") -> F | E11: =E9-E10 -> 555966.5 | F11: =(E11-H11)/H11 -> -0.14930932 | G11: =IF(E11>=H11,"F","U") -> U | H11: =H9-H10 -> 653547.19 | I11: =(H11-B11)/B11 -> 0.081499635 | J11: =IF(B11>=H11,"F","U") -> U

Sheet Actual vs Budget
B1: Figures in INR | J1: Figures in INR
B3: Select quarter from dropdown
B4: 46112 | C4: Quarterly Variance | J4: YTD Variance
B5: Particulars | C5: Actual | E5: Budget | G5: Variance | J5: Particulars | K5: Actual | M5: Budget | O5: Variance
C6: in INR | D6: % Sales | E6: in INR | F6: % Sales | G6: in INR | H6: % Variance | K6: in INR | L6: % Sales | M6: in INR | N6: % Sales | O6: in INR | P6: % Variance
B7: Revenue | C7: =HLOOKUP($B$4,Actuals!$B$3:$G$13,2,FALSE) -> 185000 | E7: =HLOOKUP($B$4,'Forecasted Budget'!$B$3:$G$13,2,FALSE) -> 175750 | G7: =C7-E7 -> 9250 | H7: =G7/E7 -> 0.052631579 | J7: Revenue | K7: =HLOOKUP($B$4,Actuals!$I$3:$M$13,2,FALSE) -> 185000 | M7: =HLOOKUP($B$4,'Forecasted Budget'!$I$3:$M$13,2,FALSE) -> 175750 | O7: =K7-M7 -> 9250 | P7: =O7/M7 -> 0.052631579
B8: COGS | C8: =HLOOKUP($B$4,Actuals!$B$3:$G$13,3,FALSE) -> 51340.476 | D8: =C8/$C$7 -> 0.27751609 | E8: =HLOOKUP($B$4,'Forecasted Budget'!$B$3:$G$13,3,FALSE) -> 41072.381 | F8: =E8/$E$7 -> 0.23369776 | G8: =C8-E8 -> 10268.095 | H8: =G8/E8 -> 0.25 | J8: COGS | K8: =HLOOKUP($B$4,Actuals!$I$3:$M$13,3,FALSE) -> 51340.476 | L8: =K8/$K$7 -> 0.27751609 | M8: =HLOOKUP($B$4,'Forecasted Budget'!$I$3:$M$13,3,FALSE) -> 41072.381 | N8: =M8/$M$7 -> 0.23369776 | O8: =K8-M8 -> 10268.095 | P8: =O8/M8 -> 0.25
B9: Gross Profit | C9: =C7-C8 -> 133659.52 | D9: =C9/$C$7 -> 0.72248391 | E9: =E7-E8 -> 134677.62 | F9: =E9/$E$7 -> 0.76630224 | G9: =C9-E9 -> -1018.0952 | H9: =G9/E9 -> -0.0075594983 | J9: Gross Profit | K9: =K7-K8 -> 133659.52 | L9: =K9/$K$7 -> 0.72248391 | M9: =M7-M8 -> 134677.62 | N9: =M9/$M$7 -> 0.76630224 | O9: =K9-M9 -> -1018.0952 | P9: =O9/M9 -> -0.0075594983
B10: Employee Expenses | C10: =HLOOKUP($B$4,Actuals!$B$3:$G$13,5,FALSE) -> 8750 | D10: =C10/$C$7 -> 0.047297297 | E10: =HLOOKUP($B$4,'Forecasted Budget'!$B$3:$G$13,5,FALSE) -> 9275 | F10: =E10/$E$7 -> 0.052773826 | G10: =C10-E10 -> -525 | H10: =G10/E10 -> -0.056603774 | J10: Employee Expenses | K10: =HLOOKUP($B$4,Actuals!$I$3:$M$13,5,FALSE) -> 8750 | L10: =K10/$K$7 -> 0.047297297 | M10: =HLOOKUP($B$4,'Forecasted Budget'!$I$3:$M$13,5,FALSE) -> 9275 | N10: =M10/$M$7 -> 0.052773826 | O10: =K10-M10 -> -525 | P10: =O10/M10 -> -0.056603774
B11: Factory & Equipments | C11: =HLOOKUP($B$4,Actuals!$B$3:$G$13,6,FALSE) -> 5500 | D11: =C11/$C$7 -> 0.02972973 | E11: =HLOOKUP($B$4,'Forecasted Budget'!$B$3:$G$13,6,FALSE) -> 7150 | F11: =E11/$E$7 -> 0.040682788 | G11: =C11-E11 -> -1650 | H11: =G11/E11 -> -0.23076923 | J11: Factory & Equipments | K11: =HLOOKUP($B$4,Actuals!$I$3:$M$13,6,FALSE) -> 5500 | L11: =K11/$K$7 -> 0.02972973 | M11: =HLOOKUP($B$4,'Forecasted Budget'!$I$3:$M$13,6,FALSE) -> 7150 | N11: =M11/$M$7 -> 0.040682788 | O11: =K11-M11 -> -1650 | P11: =O11/M11 -> -0.23076923
B12: Depreciation Expenses | C12: =HLOOKUP($B$4,Actuals!$B$3:$G$13,7,FALSE) -> 1250 | D12: =C12/$C$7 -> 0.0067567568 | E12: =HLOOKUP($B$4,'Forecasted Budget'!$B$3:$G$13,7,FALSE) -> 1287.5 | F12: =E12/$E$7 -> 0.0073257468 | G12: =C12-E12 -> -37.5 | H12: =G12/E12 -> -0.029126214 | J12: Depreciation Expenses | K12: =HLOOKUP($B$4,Actuals!$I$3:$M$13,7,FALSE) -> 1250 | L12: =K12/$K$7 -> 0.0067567568 | M12: =HLOOKUP($B$4,'Forecasted Budget'!$I$3:$M$13,7,FALSE) -> 1287.5 | N12: =M12/$M$7 -> 0.0073257468 | O12: =K12-M12 -> -37.5 | P12: =O12/M12 -> -0.029126214
B13: Other Expenses | C13: =HLOOKUP($B$4,Actuals!$B$3:$G$13,8,FALSE) -> 500 | D13: =C13/$C$7 -> 0.0027027027 | E13: =HLOOKUP($B$4,'Forecasted Budget'!$B$3:$G$13,8,FALSE) -> 560 | F13: =E13/$E$7 -> 0.0031863442 | G13: =C13-E13 -> -60 | H13: =G13/E13 -> -0.10714286 | J13: Other Expenses | K13: =HLOOKUP($B$4,Actuals!$I$3:$M$13,8,FALSE) -> 500 | L13: =K13/$K$7 -> 0.0027027027 | M13: =HLOOKUP($B$4,'Forecasted Budget'!$I$3:$M$13,8,FALSE) -> 560 | N13: =M13/$M$7 -> 0.0031863442 | O13: =K13-M13 -> -60 | P13: =O13/M13 -> -0.10714286
B14: EBT | C14: =C9-SUM(C10:C13) -> 117659.52 | D14: =C14/$C$7 -> 0.63599743 | E14: =E9-SUM(E10:E13) -> 116405.12 | F14: =E14/$E$7 -> 0.66233354 | G14: =C14-E14 -> 1254.4048 | H14: =G14/E14 -> 0.010776199 | J14: EBT | K14: =K9-SUM(K10:K13) -> 117659.52 | L14: =K14/$K$7 -> 0.63599743 | M14: =M9-SUM(M10:M13) -> 116405.12 | N14: =M14/$M$7 -> 0.66233354 | O14: =K14-M14 -> 1254.4048 | P14: =O14/M14 -> 0.010776199
B15: Tax | C15: =HLOOKUP($B$4,Actuals!$B$3:$G$13,10,FALSE) -> 23531.905 | D15: =C15/$C$7 -> 0.12719949 | E15: =HLOOKUP($B$4,'Forecasted Budget'!$B$3:$G$13,10,FALSE) -> 37180.41 | F15: =E15/$E$7 -> 0.21155283 | G15: =C15-E15 -> -13648.505 | H15: =G15/E15 -> -0.36708861 | J15: Tax | K15: =HLOOKUP($B$4,Actuals!$I$3:$M$13,10,FALSE) -> 23531.905 | L15: =K15/$K$7 -> 0.12719949 | M15: =HLOOKUP($B$4,'Forecasted Budget'!$I$3:$M$13,10,FALSE) -> 37180.41 | N15: =M15/$M$7 -> 0.21155283 | O15: =K15-M15 -> -13648.505 | P15: =O15/M15 -> -0.36708861
B16: Net Profit | C16: =C14-C15 -> 94127.619 | D16: =C16/$C$7 -> 0.50879794 | E16: =E14-E15 -> 79224.71 | F16: =E16/$E$7 -> 0.45078071 | G16: =C16-E16 -> 14902.91 | H16: =G16/E16 -> 0.18810936 | J16: Net Profit | K16: =K14-K15 -> 94127.619 | L16: =K16/$K$7 -> 0.50879794 | M16: =M14-M15 -> 79224.71 | N16: =M16/$M$7 -> 0.45078071 | O16: =K16-M16 -> 14902.91 | P16: =O16/M16 -> 0.18810936

Sheet Actuals
B1: Figures in INR | C1: Actual | I1: Figures in INR | J1: Actual - YTD
B3: Particulars | C3: 46112 | D3: 46203 | E3: 46295 | F3: 46387 | G3: FY 2026 | I3: Particular | J3: 46112 | K3: 46203 | L3: 46295 | M3: 46387
B4: Revenue | C4: ='Income Statement'!B8 -> 185000 | D4: ='Income Statement'!C8 -> 212750 | E4: ='Income Statement'!D8 -> 244662.5 | F4: ='Income Statement'!E8 -> 282587.5 | G4: =SUM(C4:F4) -> 925000 | I4: Revenue | J4: =SUM($C4:C4) -> 185000 | K4: =SUM($C4:D4) -> 397750 | L4: =SUM($C4:E4) -> 642412.5 | M4: =SUM($C4:F4) -> 925000
B5: COGS | C5: ='Income Statement'!B9 -> 51340.476 | D5: ='Income Statement'!C9 -> 59041.548 | E5: ='Income Statement'!D9 -> 67897.78 | F5: ='Income Statement'!E9 -> 78422.577 | G5: =SUM(C5:F5) -> 256702.38 | I5: COGS | J5: =SUM($C5:C5) -> 51340.476 | K5: =SUM($C5:D5) -> 110382.02 | L5: =SUM($C5:E5) -> 178279.8 | M5: =SUM($C5:F5) -> 256702.38
B6: Gross Profit | C6: =C4-C5 -> 133659.52 | D6: =D4-D5 -> 153708.45 | E6: =E4-E5 -> 176764.72 | F6: =F4-F5 -> 204164.92 | G6: =G4-G5 -> 668297.62 | I6: Gross Profit | J6: =SUM($C6:C6) -> 133659.52 | K6: =SUM($C6:D6) -> 287367.98 | L6: =SUM($C6:E6) -> 464132.7 | M6: =SUM($C6:F6) -> 668297.62
B7: Employee Expenses | C7: =('Income Statement'!B16+'Income Statement'!B20) -> 8750 | D7: =('Income Statement'!C16+'Income Statement'!C20) -> 8787.5 | E7: =('Income Statement'!D16+'Income Statement'!D20) -> 9014.75 | F7: =('Income Statement'!E16+'Income Statement'!E20) -> 8447.75 | G7: =SUM(C7:F7) -> 35000 | I7: Employee Expenses | J7: =SUM($C7:C7) -> 8750 | K7: =SUM($C7:D7) -> 17537.5 | L7: =SUM($C7:E7) -> 26552.25 | M7: =SUM($C7:F7) -> 35000
B8: Factory & Equipments | C8: =('Income Statement'!B17+'Income Statement'!B18+'Income Statement'!B21+'Income Statement'!B22) -> 5500 | D8: =('Income Statement'!C17+'Income Statement'!C18+'Income Statement'!C21+'Income Statement'!C22) -> 5517.5 | E8: =('Income Statement'!D17+'Income Statement'!D18+'Income Statement'!D21+'Income Statement'!D22) -> 5623.55 | F8: =('Income Statement'!E17+'Income Statement'!E18+'Income Statement'!E21+'Income Statement'!E22) -> 5358.95 | G8: =SUM(C8:F8) -> 22000 | I8: Factory & Equipments | J8: =SUM($C8:C8) -> 5500 | K8: =SUM($C8:D8) -> 11017.5 | L8: =SUM($C8:E8) -> 16641.05 | M8: =SUM($C8:F8) -> 22000
B9: Depreciation Expenses | C9: ='Income Statement'!B23 -> 1250 | D9: ='Income Statement'!C23 -> 1250 | E9: ='Income Statement'!D23 -> 1250 | F9: ='Income Statement'!E23 -> 1250 | G9: =SUM(C9:F9) -> 5000 | I9: Depreciation Expenses | J9: =SUM($C9:C9) -> 1250 | K9: =SUM($C9:D9) -> 2500 | L9: =SUM($C9:E9) -> 3750 | M9: =SUM($C9:F9) -> 5000
B10: Other Expenses | C10: ='Income Statement'!B19 -> 500 | D10: ='Income Statement'!C19 -> 505 | E10: ='Income Statement'!D19 -> 535.3 | F10: ='Income Statement'!E19 -> 459.7 | G10: =SUM(C10:F10) -> 2000 | I10: Other Expenses | J10: =SUM($C10:C10) -> 500 | K10: =SUM($C10:D10) -> 1005 | L10: =SUM($C10:E10) -> 1540.3 | M10: =SUM($C10:F10) -> 2000
B11: EBT | C11: =C6-SUM(C7:C10) -> 117659.52 | D11: =D6-SUM(D7:D10) -> 137648.45 | E11: =E6-SUM(E7:E10) -> 160341.12 | F11: =F6-SUM(F7:F10) -> 188648.52 | G11: =G6-SUM(G7:G10) -> 604297.62 | I11: EBT | J11: =SUM($C11:C11) -> 117659.52 | K11: =SUM($C11:D11) -> 255307.98 | L11: =SUM($C11:E11) -> 415649.1 | M11: =SUM($C11:F11) -> 604297.62
B12: Tax | C12: ='Income Statement'!B29 -> 23531.905 | D12: ='Income Statement'!C29 -> 27529.69 | E12: ='Income Statement'!D29 -> 32068.224 | F12: ='Income Statement'!E29 -> 37729.705 | G12: =SUM(C12:F12) -> 120859.52 | I12: Tax | J12: =SUM($C12:C12) -> 23531.905 | K12: =SUM($C12:D12) -> 51061.595 | L12: =SUM($C12:E12) -> 83129.819 | M12: =SUM($C12:F12) -> 120859.52
B13: Net Profit | C13: =C11-C12 -> 94127.619 | D13: =D11-D12 -> 110118.76 | E13: =E11-E12 -> 128272.9 | F13: =F11-F12 -> 150918.82 | G13: =G11-G12 -> 483438.1 | I13: Net Profit | J13: =SUM($C13:C13) -> 94127.619 | K13: =SUM($C13:D13) -> 204246.38 | L13: =SUM($C13:E13) -> 332519.28 | M13: =SUM($C13:F13) -> 483438.1

Sheet Forecasted Budget
B1: Figures in INR | C1: Actual | I1: Figures in INR | J1: Actual - YTD
B3: Particulars | C3: 46112 | D3: 46203 | E3: 46295 | F3: 46387 | G3: FY 2026 | I3: Particular | J3: 46112 | K3: 46203 | L3: 46295 | M3: 46387
B4: Revenue | C4: =Actuals!C4*0.95 -> 175750 | D4: =Actuals!D4*0.97 -> 206367.5 | E4: =Actuals!E4*0.92 -> 225089.5 | F4: =Actuals!F4*0.92 -> 259980.5 | G4: =SUM(C4:F4) -> 867187.5 | I4: Revenue | J4: =SUM($C4:C4) -> 175750 | K4: =SUM($C4:D4) -> 382117.5 | L4: =SUM($C4:E4) -> 607207 | M4: =SUM($C4:F4) -> 867187.5
B5: COGS | C5: =Actuals!C5*0.8 -> 41072.381 | D5: =Actuals!D5*0.78 -> 46052.407 | E5: =Actuals!E5*0.82 -> 55676.179 | F5: =Actuals!F5*0.78 -> 61169.61 | G5: =SUM(C5:F5) -> 203970.58 | I5: COGS | J5: =SUM($C5:C5) -> 41072.381 | K5: =SUM($C5:D5) -> 87124.788 | L5: =SUM($C5:E5) -> 142800.97 | M5: =SUM($C5:F5) -> 203970.58
B6: Gross Profit | C6: =C4-C5 -> 134677.62 | D6: =D4-D5 -> 160315.09 | E6: =E4-E5 -> 169413.32 | F6: =F4-F5 -> 198810.89 | G6: =G4-G5 -> 663216.92 | I6: Gross Profit | J6: =SUM($C6:C6) -> 134677.62 | K6: =SUM($C6:D6) -> 294992.71 | L6: =SUM($C6:E6) -> 464406.03 | M6: =SUM($C6:F6) -> 663216.92
B7: Employee Expenses | C7: =Actuals!C7*1.06 -> 9275 | D7: =Actuals!D7*1.08 -> 9490.5 | E7: =Actuals!E7*1.1 -> 9916.225 | F7: =Actuals!F7*1.02 -> 8616.705 | G7: =SUM(C7:F7) -> 37298.43 | I7: Employee Expenses | J7: =SUM($C7:C7) -> 9275 | K7: =SUM($C7:D7) -> 18765.5 | L7: =SUM($C7:E7) -> 28681.725 | M7: =SUM($C7:F7) -> 37298.43
B8: Factory & Equipments | C8: =Actuals!C8*1.3 -> 7150 | D8: =Actuals!D8*1.35 -> 7448.625 | E8: =Actuals!E8*1.35 -> 7591.7925 | F8: =Actuals!F8*1.4 -> 7502.53 | G8: =SUM(C8:F8) -> 29692.947 | I8: Factory & Equipments | J8: =SUM($C8:C8) -> 7150 | K8: =SUM($C8:D8) -> 14598.625 | L8: =SUM($C8:E8) -> 22190.417 | M8: =SUM($C8:F8) -> 29692.947
B9: Depreciation Expenses | C9: =Actuals!C9*1.03 -> 1287.5 | D9: =Actuals!D9*1.04 -> 1300 | E9: =Actuals!E9*1.09 -> 1362.5 | F9: =Actuals!F9*1.01 -> 1262.5 | G9: =SUM(C9:F9) -> 5212.5 | I9: Depreciation Expenses | J9: =SUM($C9:C9) -> 1287.5 | K9: =SUM($C9:D9) -> 2587.5 | L9: =SUM($C9:E9) -> 3950 | M9: =SUM($C9:F9) -> 5212.5
B10: Other Expenses | C10: =Actuals!C10*1.12 -> 560 | D10: =Actuals!D10*1.12 -> 565.6 | E10: =Actuals!E10*1.1 -> 588.83 | F10: =Actuals!F10*1.13 -> 519.461 | G10: =SUM(C10:F10) -> 2233.891 | I10: Other Expenses | J10: =SUM($C10:C10) -> 560 | K10: =SUM($C10:D10) -> 1125.6 | L10: =SUM($C10:E10) -> 1714.43 | M10: =SUM($C10:F10) -> 2233.891
B11: EBT | C11: =C6-SUM(C7:C10) -> 116405.12 | D11: =D6-SUM(D7:D10) -> 141510.37 | E11: =E6-SUM(E7:E10) -> 149953.97 | F11: =F6-SUM(F7:F10) -> 180909.69 | G11: =G6-SUM(G7:G10) -> 588779.15 | I11: EBT | J11: =SUM($C11:C11) -> 116405.12 | K11: =SUM($C11:D11) -> 257915.49 | L11: =SUM($C11:E11) -> 407869.46 | M11: =SUM($C11:F11) -> 588779.15
B12: Tax | C12: =Actuals!C12*1.58 -> 37180.41 | D12: =Actuals!D12*0.14 -> 3854.1567 | E12: =Actuals!E12*0.95 -> 30464.813 | F12: =Actuals!F12*0.69 -> 26033.496 | G12: =SUM(C12:F12) -> 97532.875 | I12: Tax | J12: =SUM($C12:C12) -> 37180.41 | K12: =SUM($C12:D12) -> 41034.566 | L12: =SUM($C12:E12) -> 71499.379 | M12: =SUM($C12:F12) -> 97532.875
B13: Net Profit | C13: =C11-C12 -> 79224.71 | D13: =D11-D12 -> 137656.21 | E13: =E11-E12 -> 119489.16 | F13: =F11-F12 -> 154876.2 | G13: =G11-G12 -> 491246.28 | I13: Net Profit | J13: =SUM($C13:C13) -> 79224.71 | K13: =SUM($C13:D13) -> 216880.92 | L13: =SUM($C13:E13) -> 336370.08 | M13: =SUM($C13:F13) -> 491246.28

Sheet Master Budget
A2: Sales Budget
A3: Product | B3: Units sold | C3: Selling price per unit (INR) | D3: Total Sales Revenue (INR)
A4: Nameplates | B4: 2000 | C4: 200 | D4: =B4*C4 -> 400000
A5: Frames | B5: 1500 | C5: 150 | D5: =B5*C5 -> 225000
A6: Engraved Items | B6: 1000 | C6: 300 | D6: =B6*C6 -> 300000
A7: Total Sales Revenue (INR) | D7: =SUM(D4:D6) -> 925000
A10: Production Budget | B10: Nameplates | C10: Frames | D10: Engraved Items | E10: FY26 | F10: FY27 | G10: FY28 | H10: FY29
A11: Budgeted units to be sold | B11: =B4 -> 2000 | C11: =B5 -> 1500 | D11: =B6 -> 1000 | E11: =SUM(B11:D11) -> 4500 | F11: =E11*1.1 -> 4950 | G11: =F11*1.1 -> 5445 | H11: =G11*1.1 -> 5989.5
A12: Closing inventory of finished goods | B12: =B11*0.1 -> 200 | C12: =C11*0.1 -> 150 | D12: =D11*0.1 -> 100 | E12: =SUM(B12:D12) -> 450 | F12: =F11*0.1 -> 495 | G12: =G11*0.1 -> 544.5 | H12: =H11*0.1 -> 598.95
A13: Total inventory | B13: =B11+B12 -> 2200 | C13: =C11+C12 -> 1650 | D13: =D11+D12 -> 1100 | E13: =SUM(B13:D13) -> 4950 | F13: =SUM(F11:F12) -> 5445 | G13: =SUM(G11:G12) -> 5989.5 | H13: =SUM(H11:H12) -> 6588.45
A14: Opening inventory of finished goods | B14: =B12/2 -> 100 | C14: =C12/2 -> 75 | D14: =D12/2 -> 50 | E14: =SUM(B14:D14) -> 225 | F14: =E12 -> 450 | G14: =F12 -> 495 | H14: =G12 -> 544.5
A15: Total finished goods to be produced | B15: =B13-B14 -> 2100 | C15: =C13-C14 -> 1575 | D15: =D13-D14 -> 1050 | E15: =SUM(B15:D15) -> 4725 | F15: =F13-F14 -> 4995 | G15: =G13-G14 -> 5494.5 | H15: =H13-H14 -> 6043.95
A17: Monthtly production requirement | B17: =B15/12 -> 175 | C17: =C15/12 -> 131.25 | D17: =D15/12 -> 87.5
A18: Weekly production requirement | B18: =B17/4 -> 43.75 | C18: =C17/4 -> 32.8125 | D18: =D17/4 -> 21.875
A19: Daily production requirement | B19: =B18/6 -> 7.2916667 | C19: =C18/6 -> 5.46875 | D19: =D18/6 -> 3.6458333
A22: Direct Materials Usage Budget | B22: Nameplates | C22: Frames | D22: Engraved Items
A23: Total units of DM required | B23: =B15 -> 2100 | C23: =C15 -> 1575 | D23: =D15 -> 1050
A24: Quantity of DM (kg/unit) | B24: 2 | C24: 1.5 | D24: 1
A25: Total quantity of DM to be used | B25: =B23*B24 -> 4200 | C25: =C23*C24 -> 2362.5 | D25: =D23*D24 -> 1050
A26: Cost Budget
A27: Total quantity of DM to be used | B27: =B25 -> 4200 | C27: =C25 -> 2362.5 | D27: =D25 -> 1050
A28: Avg price per unit | B28: 5 | C28: 7 | D28: 10
A29: Total cost of DM to be used (INR) | B29: =B27*B28 -> 21000 | C29: =C27*C28 -> 16537.5 | D29: =D27*D28 -> 10500
A30: Total cost of DM to be used for all products (INR) | D30: =SUM(B29:D29) -> 48037.5
A33: Direct Materials Purchases Budget | B33: Nameplates | C33: Frames | D33: Engraved Items
A34: Total units of DM required | B34: =B23 -> 2100 | C34: =C23 -> 1575 | D34: =D23 -> 1050
A35: Closing inventory of DM | B35: =B34*0.15 -> 315 | C35: =C34*0.15 -> 236.25 | D35: =D34*0.15 -> 157.5
A36: Total inventory of DM | B36: =B34+B35 -> 2415 | C36: =C34+C35 -> 1811.25 | D36: =D34+D35 -> 1207.5
A37: Opening inventory of DM | B37: =B35/2 -> 157.5 | C37: =C35/2 -> 118.125 | D37: =D35/2 -> 78.75
A38: Total DM units to be purchased | B38: =B36-B37 -> 2257.5 | C38: =C36-C37 -> 1693.125 | D38: =D36-D37 -> 1128.75
A39: Cost Budget
A40: Total DM units to be purchased | B40: =B38 -> 2257.5 | C40: =C38 -> 1693.125 | D40: =D38 -> 1128.75
A41: Quantity of DM (kg/unit) | B41: =B24 -> 2 | C41: =C24 -> 1.5 | D41: =D24 -> 1
A42: Total quantity of DM to be purchased | B42: =B40*B41 -> 4515 | C42: =C40*C41 -> 2539.6875 | D42: =D40*D41 -> 1128.75
A43: Avg price per unit | B43: =B28 -> 5 | C43: =C28 -> 7 | D43: =D28 -> 10
A44: Total cost of DM to be purchased (INR) | B44: =B42*B43 -> 22575 | C44: =C42*C43 -> 17777.812 | D44: =D42*D43 -> 11287.5
A45: Total cost of DM to be purchased for all products (INR) | D45: =SUM(B44:D44) -> 51640.312
A48: Direct Labour Budget | B48: Nameplates | C48: Frames | D48: Engraved Items
A49: Avg rate per hour | B49: 120 | C49: 80 | D49: 40
A50: Avg hourly time per unit | B50: 0.25 | C50: 0.5 | D50: 0.75
...

Sheet Income Statement
A1: Income Statement
B2: Quarterly | F2: Yearly
B3: Q1 | C3: Q2 | D3: Q3 | E3: Q4 | F3: FY2026 | G3: FY2027 | H3: FY2028 | I3: FY2029 | J3: FY2030
A4: Revenue
A5: Nameplates | B5: ='Master Budget'!D4/5 -> 80000 | C5: =B5*1.15 -> 92000 | D5: =C5*1.15 -> 105800 | E5: ='Master Budget'!D4-SUM('Income Statement'!B5:D5) -> 122200 | F5: =SUM(B5:E5) -> 400000 | G5: =F5*1.1 -> 440000 | H5: =G5*1.1 -> 484000 | I5: =H5*1.1 -> 532400 | J5: =I5*1.1 -> 585640
A6: Frames | B6: ='Master Budget'!D5/5 -> 45000 | C6: =B6*1.15 -> 51750 | D6: =C6*1.15 -> 59512.5 | E6: ='Master Budget'!D5-SUM('Income Statement'!B6:D6) -> 68737.5 | F6: =SUM(B6:E6) -> 225000 | G6: =F6*1.12 -> 252000 | H6: =G6*1.12 -> 282240 | I6: =H6*1.12 -> 316108.8 | J6: =I6*1.12 -> 354041.86
A7: Engraved Items | B7: ='Master Budget'!D6/5 -> 60000 | C7: =B7*1.15 -> 69000 | D7: =C7*1.15 -> 79350 | E7: ='Master Budget'!D6-SUM('Income Statement'!B7:D7) -> 91650 | F7: =SUM(B7:E7) -> 300000 | G7: =F7*1.5 -> 450000 | H7: =G7*1.5 -> 675000 | I7: =H7*1.5 -> 1012500 | J7: =I7*1.5 -> 1518750
A8: Total | B8: =SUM(B5:B7) -> 185000 | C8: =SUM(C5:C7) -> 212750 | D8: =SUM(D5:D7) -> 244662.5 | E8: =SUM(E5:E7) -> 282587.5 | F8: =SUM(F5:F7) -> 925000 | G8: =SUM(G5:G7) -> 1142000 | H8: =SUM(H5:H7) -> 1441240 | I8: =SUM(I5:I7) -> 1861008.8 | J8: =SUM(J5:J7) -> 2458431.9
A9: COGS | B9: =SUM(B10:B12) -> 51340.476 | C9: =SUM(C10:C12) -> 59041.548 | D9: =SUM(D10:D12) -> 67897.78 | E9: =SUM(E10:E12) -> 78422.577 | F9: =SUM(F10:F12) -> 256702.38 | G9: =SUM(G10:G12) -> 309487.62 | H9: =SUM(H10:H12) -> 380359.47 | I9: =SUM(I10:I12) -> 477440.7 | J9: =SUM(J10:J12) -> 612812.63
A10: Nameplates | B10: ='Master Budget'!B111/5 -> 19047.619 | C10: =B10*1.15 -> 21904.762 | D10: =C10*1.15 -> 25190.476 | E10: ='Master Budget'!B111-SUM('Income Statement'!B10:D10) -> 29095.238 | F10: =SUM(B10:E10) -> 95238.095 | G10: =F10*1.1 -> 104761.9 | H10: =G10*1.1 -> 115238.1 | I10: =H10*1.1 -> 126761.9 | J10: =I10*1.1 -> 139438.1
A11: Frames | B11: ='Master Budget'!C111/5 -> 19721.429 | C11: =B11*1.15 -> 22679.643 | D11: =C11*1.15 -> 26081.589 | E11: ='Master Budget'!C111-SUM('Income Statement'!B11:D11) -> 30124.482 | F11: =SUM(B11:E11) -> 98607.143 | G11: =F11*1.12 -> 110440 | H11: =G11*1.12 -> 123692.8 | I11: =H11*1.12 -> 138535.94 | J11: =I11*1.12 -> 155160.25
A12: Engraved Items | B12: ='Master Budget'!D111/5 -> 12571.429 | C12: =B12*1.15 -> 14457.143 | D12: =C12*1.15 -> 16625.714 | E12: ='Master Budget'!D111-SUM('Income Statement'!B12:D12) -> 19202.857 | F12: =SUM(B12:E12) -> 62857.143 | G12: =F12*1.5 -> 94285.714 | H12: =G12*1.5 -> 141428.57 | I12: =H12*1.5 -> 212142.86 | J12: =I12*1.5 -> 318214.29
A13: Gross Profit | B13: =B8-B9 -> 133659.52 | C13: =C8-C9 -> 153708.45 | D13: =D8-D9 -> 176764.72 | E13: =E8-E9 -> 204164.92 | F13: =F8-F9 -> 668297.62 | G13: =G8-G9 -> 832512.38 | H13: =H8-H9 -> 1060880.5 | I13: =I8-I9 -> 1383568.1 | J13: =J8-J9 -> 1845619.2
A14: Gross Profit Margin | B14: =B13/B8 -> 0.72248391 | C14: =C13/C8 -> 0.72248391 | D14: =D13/D8 -> 0.72248391 | E14: =E13/E8 -> 0.72248391 | F14: =F13/F8 -> 0.72248391 | G14: =G13/G8 -> 0.72899508 | H14: =H13/H8 -> 0.73608874 | I14: =I13/I8 -> 0.7434506 | J14: =J13/J8 -> 0.75073028
A15: Operating Expenses
A16: Indirect manufacturing labor | B16: ='Master Budget'!D61/4 -> 3750 | C16: =B16*1.01 -> 3787.5 | D16: =C16*1.06 -> 4014.75 | E16: ='Master Budget'!D61-SUM('Income Statement'!B16:D16) -> 3447.75 | F16: =SUM(B16:E16) -> 15000 | G16: =F16*1.1 -> 16500 | H16: =G16*1.1 -> 18150 | I16: =H16*1.1 -> 19965 | J16: =I16*1.1 -> 21961.5
A17: Equipment maintenance | B17: ='Master Budget'!D62/4 -> 1250 | C17: =B17*1.01 -> 1262.5 | D17: =C17*1.06 -> 1338.25 | E17: ='Master Budget'!D62-SUM('Income Statement'!B17:D17) -> 1149.25 | F17: =SUM(B17:E17) -> 5000 | G17: =F17*1.05 -> 5250 | H17: =G17*1.05 -> 5512.5 | I17: =H17*1.05 -> 5788.125 | J17: =I17*1.05 -> 6077.5312
A18: Utilities | B18: ='Master Budget'!D63/4 -> 500 | C18: =B18*1.01 -> 505 | D18: =C18*1.06 -> 535.3 | E18: ='Master Budget'!D63-SUM('Income Statement'!B18:D18) -> 459.7 | F18: =SUM(B18:E18) -> 2000 | G18: =F18*1.05 -> 2100 | H18: =G18*1.05 -> 2205 | I18: =H18*1.05 -> 2315.25 | J18: =I18*1.05 -> 2431.0125
A19: Other variable costs | B19: ='Master Budget'!D64/4 -> 500 | C19: =B19*1.01 -> 505 | D19: =C19*1.06 -> 535.3 | E19: ='Master Budget'!D64-SUM('Income Statement'!B19:D19) -> 459.7 | F19: =SUM(B19:E19) -> 2000 | G19: =F19*1.05 -> 2100 | H19: =G19*1.05 -> 2205 | I19: =H19*1.05 -> 2315.25 | J19: =I19*1.05 -> 2431.0125
A20: Supervisory salaries and employee cost | B20: ='Master Budget'!B62/4 -> 5000 | C20: =B20 -> 5000 | D20: =C20 -> 5000 | E20: =D20 -> 5000 | F20: =SUM(B20:E20) -> 20000 | G20: =F20*1.05 -> 21000 | H20: =G20*1.05 -> 22050 | I20: =H20*1.05 -> 23152.5 | J20: =I20*1.05 -> 24310.125
A21: Factory Rent | B21: ='Master Budget'!B63/4 -> 2500 | C21: =B21 -> 2500 | D21: =C21 -> 2500 | E21: =D21 -> 2500 | F21: =SUM(B21:E21) -> 10000 | G21: =F21*1.05 -> 10500 | H21: =G21*1.05 -> 11025 | I21: =H21*1.05 -> 11576.25 | J21: =I21*1.05 -> 12155.062
A22: Other indirect fixed costs | B22: ='Master Budget'!B64/4 -> 1250 | C22: =B22 -> 1250 | D22: =C22 -> 1250 | E22: =D22 -> 1250 | F22: =SUM(B22:E22) -> 5000 | G22: =F22*1.05 -> 5250 | H22: =G22*1.05 -> 5512.5 | I22: =H22*1.05 -> 5788.125 | J22: =I22*1.05 -> 6077.5312
A23: Depreciation | B23: ='Master Budget'!B61/4 -> 1250 | C23: =B23 -> 1250 | D23: =C23 -> 1250 | E23: =D23 -> 1250 | F23: =SUM(B23:E23) -> 5000 | G23: =F23*1.05 -> 5250 | H23: =G23*1.05 -> 5512.5 | I23: =H23*1.05 -> 5788.125 | J23: =I23*1.05 -> 6077.5312
A24: Total Operating Expenses | B24: =SUM(B16:B23) -> 16000 | C24: =SUM(C16:C23) -> 16060 | D24: =SUM(D16:D23) -> 16423.6 | E24: =SUM(E16:E23) -> 15516.4 | F24: =SUM(F16:F23) -> 64000 | G24: =SUM(G16:G23) -> 67950 | H24: =SUM(H16:H23) -> 72172.5 | I24: =SUM(I16:I23) -> 76688.625 | J24: =SUM(J16:J23) -> 81521.306
A25: Operating Income (EBIT/PBIT) | B25: =B13-B24 -> 117659.52 | C25: =C13-C24 -> 137648.45 | D25: =D13-D24 -> 160341.12 | E25: =E13-E24 -> 188648.52 | F25: =F13-F24 -> 604297.62 | G25: =G13-G24 -> 764562.38 | H25: =H13-H24 -> 988708.03 | I25: =I13-I24 -> 1306879.5 | J25: =J13-J24 -> 1764097.9
A26: Operating Profit Margin | B26: =B25/B8 -> 0.63599743 | C26: =C25/C8 -> 0.64699625 | D26: =D25/D8 -> 0.65535634 | E26: =E25/E8 -> 0.66757561 | F26: =F25/F8 -> 0.65329472 | G26: =G25/G8 -> 0.6694942 | H26: =H25/H8 -> 0.68601207 | I26: =I25/I8 -> 0.7022425 | J26: =J25/J8 -> 0.7175704
A27: Interest Expenses | B27: 0 | C27: 0 | D27: 0 | E27: 0 | F27: =SUM(B27:E27) -> 0
A28: EBT/PBT | B28: =B25-B27 -> 117659.52 | C28: =C25-C27 -> 137648.45 | D28: =D25-D27 -> 160341.12 | E28: =E25-E27 -> 188648.52 | F28: =F25-F27 -> 604297.62 | G28: =G25-G27 -> 764562.38 | H28: =H25-H27 -> 988708.03 | I28: =I25-I27 -> 1306879.5 | J28: =J25-J27 -> 1764097.9
A29: Tax | B29: =B28*0.2 -> 23531.905 | C29: =C28*0.2 -> 27529.69 | D29: =D28*0.2 -> 32068.224 | E29: =E28*0.2 -> 37729.705 | F29: =SUM(B29:E29) -> 120859.52 | G29: =G28*0.2 -> 152912.48 | H29: =H28*0.2 -> 197741.61 | I29: =I28*0.2 -> 261375.9 | J29: =J28*0.2 -> 352819.58
A30: Net Income | B30: =B28-B29 -> 94127.619 | C30: =C28-C29 -> 110118.76 | D30: =D28-D29 -> 128272.9 | E30: =E28-E29 -> 150918.82 | F30: =F28-F29 -> 483438.1 | G30: =G28-G29 -> 611649.9 | H30: =H28-H29 -> 790966.43 | I30: =I28-I29 -> 1045503.6 | J30: =J28-J29 -> 1411278.3
A31: Profit Margin | B31: =B30/B8 -> 0.50879794 | C31: =C30/C8 -> 0.517597 | D31: =D30/D8 -> 0.52428507 | E31: =E30/E8 -> 0.53406049 | F31: =F30/F8 -> 0.52263578 | G31: =G30/G8 -> 0.53559536 | H31: =H30/H8 -> 0.54880965 | I31: =I30/I8 -> 0.561794 | J31: =J30/J8 -> 0.57405632
A33: EBITDA | B33: =B25+B23 -> 118909.52 | C33: =C25+C23 -> 138898.45 | D33: =D25+D23 -> 161591.12 | E33: =E25+E23 -> 189898.52 | F33: =F25+F23 -> 609297.62 | G33: =G25+G23 -> 769812.38 | H33: =H25+H23 -> 994220.53 | I33: =I25+I23 -> 1312667.6 | J33: =J25+J23 -> 1770175.5
A34: EBITDA Margin | B34: =B33/B8 -> 0.64275418 | C34: =C33/C8 -> 0.65287169 | D34: =D33/D8 -> 0.66046542 | E34: =E33/E8 -> 0.67199902 | F34: =F33/F8 -> 0.65870013 | G34: =G33/G8 -> 0.6740914 | H34: =H33/H8 -> 0.6898369 | I34: =I33/I8 -> 0.70535271 | J34: =J33/J8 -> 0.72004251

Sheet Data Source
B1: Quarters
B2: 46112
B3: 46203
B4: 46295
B5: 46387
